<?xml version="1.0" ?>
<robot name="jetbot" xmlns:xacro="http://www.ros.org/wiki/xacro">

<xacro:include filename="$(find jetbot_description)/urdf/materials.xacro" />
<xacro:include filename="$(find jetbot_description)/urdf/jetbot.trans" />
<xacro:include filename="$(find jetbot_description)/urdf/jetbot.gazebo" />
<link name="base_link">
  <inertial>
    <origin xyz="-0.003223302532609276 0.020284756528773918 0.07399803282464708" rpy="0 0 0"/>
    <mass value="3.906478663109029"/>
    <inertia ixx="0.005106" iyy="0.003423" izz="0.006676" ixy="2e-06" iyz="-0.000298" ixz="8e-06"/>
  </inertial>
  <visual>
    <origin xyz="0 0 0" rpy="0 0 0"/>
    <geometry>
      <mesh filename="package://jetbot_description/meshes/base_link.stl" scale="0.001 0.001 0.001"/>
    </geometry>
    <material name="silver"/>
  </visual>
  <collision>
    <origin xyz="0 0 0" rpy="0 0 0"/>
    <geometry>
      <mesh filename="package://jetbot_description/meshes/base_link.stl" scale="0.001 0.001 0.001"/>
    </geometry>
  </collision>
</link>

<link name="lift_wheel_1">
  <inertial>
    <origin xyz="0.0037650477608098254 -5.204170427930421e-18 -1.3877787807814457e-17" rpy="0 0 0"/>
    <mass value="0.12484885554906687"/>
    <inertia ixx="5.5e-05" iyy="2.8e-05" izz="2.8e-05" ixy="-0.0" iyz="-0.0" ixz="0.0"/>
  </inertial>
  <visual>
    <origin xyz="-0.048874 -0.01 -0.06" rpy="0 0 0"/>
    <geometry>
      <mesh filename="package://jetbot_description/meshes/lift_wheel_1.stl" scale="0.001 0.001 0.001"/>
    </geometry>
    <material name="silver"/>
  </visual>
  <collision>
    <origin xyz="-0.048874 -0.01 -0.06" rpy="0 0 0"/>
    <geometry>
      <mesh filename="package://jetbot_description/meshes/lift_wheel_1.stl" scale="0.001 0.001 0.001"/>
    </geometry>
  </collision>
</link>

<link name="right_wheel_1">
  <inertial>
    <origin xyz="-0.0037658164367210395 -5.204170427930421e-18 -1.3877787807814457e-17" rpy="0 0 0"/>
    <mass value="0.12484885554906687"/>
    <inertia ixx="5.5e-05" iyy="2.8e-05" izz="2.8e-05" ixy="0.0" iyz="-0.0" ixz="0.0"/>
  </inertial>
  <visual>
    <origin xyz="0.055126 -0.01 -0.06" rpy="0 0 0"/>
    <geometry>
      <mesh filename="package://jetbot_description/meshes/right_wheel_1.stl" scale="0.001 0.001 0.001"/>
    </geometry>
    <material name="silver"/>
  </visual>
  <collision>
    <origin xyz="0.055126 -0.01 -0.06" rpy="0 0 0"/>
    <geometry>
      <mesh filename="package://jetbot_description/meshes/right_wheel_1.stl" scale="0.001 0.001 0.001"/>
    </geometry>
  </collision>
</link>

<link name="camera_1_1">
  <inertial>
    <origin xyz="1.6352828422980248e-10 0.003363891386513787 -3.867160170006878e-07" rpy="0 0 0"/>
    <mass value="0.001463228414154849"/>
    <inertia ixx="0.0" iyy="0.0" izz="0.0" ixy="0.0" iyz="0.0" ixz="-0.0"/>
  </inertial>
  <visual>
    <origin xyz="0.003 -0.07659 -0.121017" rpy="0 0 0"/>
    <geometry>
      <mesh filename="package://jetbot_description/meshes/camera_1_1.stl" scale="0.001 0.001 0.001"/>
    </geometry>
    <material name="silver"/>
  </visual>
  <collision>
    <origin xyz="0.003 -0.07659 -0.121017" rpy="0 0 0"/>
    <geometry>
      <mesh filename="package://jetbot_description/meshes/camera_1_1.stl" scale="0.001 0.001 0.001"/>
    </geometry>
  </collision>
</link>

<link name="imu2_1">
  <inertial>
    <origin xyz="6.91634249871953e-14 -1.3877787807814457e-17 0.043254028613950474" rpy="0 0 0"/>
    <mass value="0.07443112556922707"/>
    <inertia ixx="5.2e-05" iyy="5.2e-05" izz="1e-06" ixy="-0.0" iyz="0.0" ixz="-0.0"/>
  </inertial>
  <visual>
    <origin xyz="-0.03 0.03 -0.087" rpy="0 0 0"/>
    <geometry>
      <mesh filename="package://jetbot_description/meshes/imu2_1.stl" scale="0.001 0.001 0.001"/>
    </geometry>
    <material name="silver"/>
  </visual>
  <collision>
    <origin xyz="-0.03 0.03 -0.087" rpy="0 0 0"/>
    <geometry>
      <mesh filename="package://jetbot_description/meshes/imu2_1.stl" scale="0.001 0.001 0.001"/>
    </geometry>
  </collision>
</link>

<link name="imu1_1">
  <inertial>
    <origin xyz="6.915301664633944e-14 3.469446951953614e-18 0.04325402861395042" rpy="0 0 0"/>
    <mass value="0.07443112556922718"/>
    <inertia ixx="5.2e-05" iyy="5.2e-05" izz="1e-06" ixy="-0.0" iyz="0.0" ixz="-0.0"/>
  </inertial>
  <visual>
    <origin xyz="0.04 0.03 -0.087" rpy="0 0 0"/>
    <geometry>
      <mesh filename="package://jetbot_description/meshes/imu1_1.stl" scale="0.001 0.001 0.001"/>
    </geometry>
    <material name="silver"/>
  </visual>
  <collision>
    <origin xyz="0.04 0.03 -0.087" rpy="0 0 0"/>
    <geometry>
      <mesh filename="package://jetbot_description/meshes/imu1_1.stl" scale="0.001 0.001 0.001"/>
    </geometry>
  </collision>
</link>

<joint name="Revolute 4" type="continuous">
  <origin xyz="0.048874 0.01 0.06" rpy="0 0 0"/>
  <parent link="base_link"/>
  <child link="lift_wheel_1"/>
  <axis xyz="1.0 0.0 0.0"/>
</joint>

<joint name="Revolute 5" type="continuous">
  <origin xyz="-0.055126 0.01 0.06" rpy="0 0 0"/>
  <parent link="base_link"/>
  <child link="right_wheel_1"/>
  <axis xyz="-1.0 0.0 0.0"/>
</joint>

<joint name="Rigid 6" type="fixed">
  <origin xyz="-0.003 0.07659 0.121017" rpy="0 0 0"/>
  <parent link="base_link"/>
  <child link="camera_1_1"/>
</joint>

<joint name="Rigid 7" type="fixed">
  <origin xyz="0.03 -0.03 0.087" rpy="0 0 0"/>
  <parent link="base_link"/>
  <child link="imu2_1"/>
</joint>

<joint name="Rigid 8" type="fixed">
  <origin xyz="-0.04 -0.03 0.087" rpy="0 0 0"/>
  <parent link="base_link"/>
  <child link="imu1_1"/>
</joint>

</robot>
